INFO 03-26 22:47:33 [__init__.py:260] No platform detected, vLLM is running on UnspecifiedPlatform
No CUDA devices are available.
AceGPT-v2-32B-Chat,AceGPT-v2-70B-Chat,Awqward2.5-32B-Instruct,calme-2.1-qwen2.5-72b,Cogito-R1,calme-2.2-qwen2.5-72b,free-evo-qwen72b-v0.8-re,lambda-qwen2.5-32b-dpo-test,Llama-3.3-70B-Instruct,Qwen2-72B,Qwen2.5-32B-Instruct,Qwen2.5-32B-Instruct-abliterated-v2,Qwen2.5-32B-Instruct-CFT,Qwen2.5-72B-Instruct,Qwentile2.5-32B-Instruct,Rombos-LLM-V2.5-Qwen-72b,Saka-14B,SakaMoe-3x14B-Instruct,tempmotacilla-cinerea-0308,Ultiima-72B
['AceGPT-v2-32B-Chat', 'AceGPT-v2-70B-Chat', 'Awqward2.5-32B-Instruct', 'calme-2.1-qwen2.5-72b', 'Cogito-R1', 'calme-2.2-qwen2.5-72b', 'free-evo-qwen72b-v0.8-re', 'lambda-qwen2.5-32b-dpo-test', 'Llama-3.3-70B-Instruct', 'Qwen2-72B', 'Qwen2.5-32B-Instruct', 'Qwen2.5-32B-Instruct-abliterated-v2', 'Qwen2.5-32B-Instruct-CFT', 'Qwen2.5-72B-Instruct', 'Qwentile2.5-32B-Instruct', 'Rombos-LLM-V2.5-Qwen-72b', 'Saka-14B', 'SakaMoe-3x14B-Instruct', 'tempmotacilla-cinerea-0308', 'Ultiima-72B']
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
  0%|          | 0/20 [00:00<?, ?it/s]  0%|          | 0/20 [00:02<?, ?it/s]
Processing model: AceGPT-v2-32B-Chat
Traceback (most recent call last):
  File "/home/guangyi.liu/.conda/envs/reasoners/lib/python3.10/site-packages/httpx/_transports/default.py", line 101, in map_httpcore_exceptions
    yield
  File "/home/guangyi.liu/.conda/envs/reasoners/lib/python3.10/site-packages/httpx/_transports/default.py", line 250, in handle_request
    resp = self._pool.handle_request(req)
  File "/home/guangyi.liu/.conda/envs/reasoners/lib/python3.10/site-packages/httpcore/_sync/connection_pool.py", line 256, in handle_request
    raise exc from None
  File "/home/guangyi.liu/.conda/envs/reasoners/lib/python3.10/site-packages/httpcore/_sync/connection_pool.py", line 236, in handle_request
    response = connection.handle_request(
  File "/home/guangyi.liu/.conda/envs/reasoners/lib/python3.10/site-packages/httpcore/_sync/connection.py", line 103, in handle_request
    return self._connection.handle_request(request)
  File "/home/guangyi.liu/.conda/envs/reasoners/lib/python3.10/site-packages/httpcore/_sync/http11.py", line 136, in handle_request
    raise exc
  File "/home/guangyi.liu/.conda/envs/reasoners/lib/python3.10/site-packages/httpcore/_sync/http11.py", line 86, in handle_request
    self._send_request_headers(**kwargs)
  File "/home/guangyi.liu/.conda/envs/reasoners/lib/python3.10/site-packages/httpcore/_sync/http11.py", line 144, in _send_request_headers
    with map_exceptions({h11.LocalProtocolError: LocalProtocolError}):
  File "/home/guangyi.liu/.conda/envs/reasoners/lib/python3.10/contextlib.py", line 153, in __exit__
    self.gen.throw(typ, value, traceback)
  File "/home/guangyi.liu/.conda/envs/reasoners/lib/python3.10/site-packages/httpcore/_exceptions.py", line 14, in map_exceptions
    raise to_exc(exc) from exc
httpcore.LocalProtocolError: Illegal header value b'Bearer '

The above exception was the direct cause of the following exception:

Traceback (most recent call last):
  File "/home/guangyi.liu/.conda/envs/reasoners/lib/python3.10/site-packages/openai/_base_client.py", line 955, in _request
    response = self._client.send(
  File "/home/guangyi.liu/.conda/envs/reasoners/lib/python3.10/site-packages/httpx/_client.py", line 914, in send
    response = self._send_handling_auth(
  File "/home/guangyi.liu/.conda/envs/reasoners/lib/python3.10/site-packages/httpx/_client.py", line 942, in _send_handling_auth
    response = self._send_handling_redirects(
  File "/home/guangyi.liu/.conda/envs/reasoners/lib/python3.10/site-packages/httpx/_client.py", line 979, in _send_handling_redirects
    response = self._send_single_request(request)
  File "/home/guangyi.liu/.conda/envs/reasoners/lib/python3.10/site-packages/httpx/_client.py", line 1014, in _send_single_request
    response = transport.handle_request(request)
  File "/home/guangyi.liu/.conda/envs/reasoners/lib/python3.10/site-packages/httpx/_transports/default.py", line 249, in handle_request
    with map_httpcore_exceptions():
  File "/home/guangyi.liu/.conda/envs/reasoners/lib/python3.10/contextlib.py", line 153, in __exit__
    self.gen.throw(typ, value, traceback)
  File "/home/guangyi.liu/.conda/envs/reasoners/lib/python3.10/site-packages/httpx/_transports/default.py", line 118, in map_httpcore_exceptions
    raise mapped_exc(message) from exc
httpx.LocalProtocolError: Illegal header value b'Bearer '

The above exception was the direct cause of the following exception:

Traceback (most recent call last):
  File "/home/guangyi.liu/ziqiao/De-Arena/run_response.py", line 687, in <module>
    fire.Fire(run_all_models(output_dir=args.output_dir, model_names=args.model_names, path=args.path, openai_api=args.openai_api, tensor_parallel_size=args.tensor_parallel_size))
  File "/home/guangyi.liu/ziqiao/De-Arena/run_response.py", line 612, in run_all_models
    responses = run_openai_model(batch_prompts, model_name, client, temperature, 2048)
  File "/home/guangyi.liu/ziqiao/De-Arena/run_response.py", line 371, in run_openai_model
    completion = client.chat.completions.create(
  File "/home/guangyi.liu/.conda/envs/reasoners/lib/python3.10/site-packages/openai/_utils/_utils.py", line 279, in wrapper
    return func(*args, **kwargs)
  File "/home/guangyi.liu/.conda/envs/reasoners/lib/python3.10/site-packages/openai/resources/chat/completions/completions.py", line 914, in create
    return self._post(
  File "/home/guangyi.liu/.conda/envs/reasoners/lib/python3.10/site-packages/openai/_base_client.py", line 1242, in post
    return cast(ResponseT, self.request(cast_to, opts, stream=stream, stream_cls=stream_cls))
  File "/home/guangyi.liu/.conda/envs/reasoners/lib/python3.10/site-packages/openai/_base_client.py", line 919, in request
    return self._request(
  File "/home/guangyi.liu/.conda/envs/reasoners/lib/python3.10/site-packages/openai/_base_client.py", line 979, in _request
    return self._retry_request(
  File "/home/guangyi.liu/.conda/envs/reasoners/lib/python3.10/site-packages/openai/_base_client.py", line 1057, in _retry_request
    return self._request(
  File "/home/guangyi.liu/.conda/envs/reasoners/lib/python3.10/site-packages/openai/_base_client.py", line 979, in _request
    return self._retry_request(
  File "/home/guangyi.liu/.conda/envs/reasoners/lib/python3.10/site-packages/openai/_base_client.py", line 1057, in _retry_request
    return self._request(
  File "/home/guangyi.liu/.conda/envs/reasoners/lib/python3.10/site-packages/openai/_base_client.py", line 989, in _request
    raise APIConnectionError(request=request) from err
openai.APIConnectionError: Connection error.
